<?xml version="1.0"?>

<robot  xmlns:xacro="http://www.ros.org/xacro">
  <xacro:include filename = "inertia.xacro"/>
  <macro name = "wheelz" params = "name">
        <link name="${name}">
            <visual>
                <origin rpy="1.57079632679 0 0" xyz="0 0 0"/>
                <geometry>
                <cylinder length="0.025" radius="0.06"/>
                </geometry>
                <material name="Black"/>
            </visual>
            <collision>
                <origin rpy="0 1.507 1.507" xyz = "0 0 0"/>
                <geometry>
                    <cylinder length="0.025" radius="0.06"/>
                </geometry>
            </collision>
            <inertial>
                 <origin rpy="0 1.507 1.507" xyz = "0 0 0"/>
                <mass value="0.2"/>
                <xacro:cy_inertia mass="0.2" r="0.06" l="0.025" />
            </inertial>
        </link>
    </macro>

    <macro name="jointz" params="name child origin_xyz">
        <joint name="${name}" type="continuous">
            <axis xyz="0 1 0"/>
            <parent link="base_link"/>
            <child link="${child}"/>
            <origin rpy="0 0 0" xyz="${origin_xyz}"/>
        </joint>
    </macro>
    
</robot>
